Workbook

Sheet Best scenario
A1: EMILY'S RETIREMENT MODEL
G2: 0.4
A3: Parameter | G3: 0.3
A4: current salary: | B4: 70000 | C4: (rand) | D4: =RAND() -> 0.58933928 | G4: 0.3
A5: average growth rate/ yearly （ μ）： | B5: 0.035
A6: Standard variation（σ）： | B6: 0.007
A7: Estimated growth rate(norm) | B7: =_xlfn.NORM.INV(D4,B5,B6) -> 0.03658092
A8: Estimated salary | B8: =B4*(1+B7) -> 72560.664
A9: Contribution rate from Emily | B9: 0.1 | C9: 0.03 | D9: 0.06 | E9: 0.1
A10: superannuation rate from company | B10: 0.021 | C10: Deduct ESCT tax ($57,601 – $84,000) | D10: ESCT tax (> $84,000) | E10: Contribute based on pre-tax salary.
A11: KiwiSaver revenue tax(before retirement) | B11: 0.28
A12: KiwiSaver revenue tax(after retirement) | C12: NZ Super+bank intrest+fund revenue
A13: NZ Super(every 2 weeks) | B13: 1076.84
A14: NZ Super tax rate
A15: superannuation compensation from goverment | B15: =IF(B8*B9>C16,D16,B8*B9*50%) -> 521.43 | C15: Min personal contribute | D15: Max Member Tax Credit
C16: 1042.86 | D16: 521.43
A17: Annual Bank Savings | B17: =C18*(1+D18) -> 5581.242 | C17: Money saved per year | D17: Rate
C18: 5364 | D18: 0.0405
A19: Decision Variables | B19: Current allocation | C19: Annual Growth Rate | D19: Volatility （SD）
A20: Harbor safe | B20: 0.1 | C20: 0.0375 | D20: 0.05
A21: Horizon | B21: 0.25 | C21: 0.065 | D21: 0.105
A22: Skyhigh | B22: 0.65 | C22: 0.1025 | D22: 0.2075
A23: Total | B23: =SUM(B20:B22) -> 1
A24: Retirement age | B24: 65 | C24: 60 | D24: 63 | E24: 65 | F24: 0.03
B25: NORM.INV(D4,B5,B6) | C25: C19*(1+B20) | D25: IF(C10<84000,3%*(1-C13),3%*(1-D13)) | E25: IF(B8*B9>C13,D13,B8*B9*50%) | F25: C20*(B11+D20)+B14
A26: Year old（30-65 years old） | B26: Salary growth rate | C26: estimated salary | D26: superannuation rate from company | E26: superannuation compensation from gov | F26: Annual superannuation | G26: Harbor safe growth rate | H26: Harborsafe Profit | I26: Harborsafe balance | J26: Horizon growth rate | K26: Horizon Profit | L26: Horizon balance | M26: Skyhigh growth rate | N26: Skyhigh revenue | O26: Skyhigh balance | P26: Total balance (pre tax) | Q26: Amount needs taxed | R26: Kiwisaver TAX | S26: NZ super | T26: Total Balance( after tax)
A27: 30 | B27: =_xlfn.NORM.INV(RAND(),$B$5,$B$6) -> 0.041523488 | C27: 70000 | D27: =IF(C27<84000,3%*(1-30%),3%*(1-33%)) -> 0.021 | E27: =$B$15 -> 521.43 | F27: =C27*($B$9+D27)+E27 -> 8991.43 | G27: =_xlfn.NORM.INV(RAND(),$C$20,$D$20) -> 0.034948841 | H27: =(F27*$B$20)*G27 -> 31.424006 | I27: =F27*B20*(1+G27) -> 930.56701 | J27: =_xlfn.NORM.INV(RAND(),$C$21,$D$21) -> 0.14736308 | K27: =F27*$B$21*J27 -> 331.2512 | L27: =F27*B21*(1+J27) -> 2579.1087 | M27: =_xlfn.NORM.INV(RAND(),$C$22,$D$22) -> 0.081547597 | N27: =F27*$B$22*M27 -> 476.59918 | O27: =F27*B22*(1+M27) -> 6321.0287 | P27: =I27+L27+O27 -> 9830.7044 | Q27: =H27+K27+N27 -> 839.27439 | R27: =IF(Q27>0,Q27*$B$11,0) -> 234.99683 | S27: =26*$B$13 -> 27997.84 | T27: =P27-R27+S27 -> 37593.548
A28: 31 | B28: =_xlfn.NORM.INV(RAND(),$B$5,$B$6) -> 0.037047358 | C28: =C27*(1+B28) -> 72593.315 | D28: =IF(C28<84000,3%*(1-30%),3%*(1-33%)) -> 0.021 | E28: =$B$15 -> 521.43 | F28: =C28*($B$9+D28)+E28 -> 9305.2211 | G28: =_xlfn.NORM.INV(RAND(),$C$20,$D$20) -> 0.098225349 | H28: =(I27+F28*$B$20)*G28 -> 182.80613 | I28: =(I27+(F28*$B$20))*(1+G28) -> 2043.8952 | J28: =_xlfn.NORM.INV(RAND(),$C$21,$D$21) -> 0.11796912 | K28: =(L27+F28*$B$21)*J28 -> 578.68738 | L28: =(L27+F28*$B$21)*(1+J28) -> 5484.1014 | M28: =_xlfn.NORM.INV(RAND(),$C$22,$D$22) -> 0.023442358 | N28: =(O27+F28*$B$22)*M28 -> 289.96843 | O28: =(O27+F28*$B$22)*(1+M28) -> 12659.391 | P28: =I28+L28+O28 -> 20187.387 | Q28: =H28+K28+N28 -> 1051.4619 | R28: =IF(Q28>0,Q28*$B$11,0) -> 294.40934 | S28: =26*$B$13 -> 27997.84 | T28: =P28-R28+S28 -> 47890.818
A29: 32 | B29: =_xlfn.NORM.INV(RAND(),$B$5,$B$6) -> 0.040017106 | C29: 70001 | D29: =IF(C29<84000,3%*(1-30%),3%*(1-33%)) -> 0.021 | E29: =$B$15 -> 521.43 | F29: =C29*($B$9+D29)+E29 -> 8991.551 | G29: =_xlfn.NORM.INV(RAND(),$C$20,$D$20) -> -0.033884684 | H29: =(I28+F29*$B$20)*G29 -> -99.724331 | I29: =(I28+(F29*$B$20))*(1+G29) -> 2843.326 | J29: =_xlfn.NORM.INV(RAND(),$C$21,$D$21) -> 0.18659343 | K29: =(L28+F29*$B$21)*J29 -> 1442.7383 | L29: =(L28+F29*$B$21)*(1+J29) -> 9174.7275 | M29: =_xlfn.NORM.INV(RAND(),$C$22,$D$22) -> 0.047880189 | N29: =(O28+F29*$B$22)*M29 -> 885.97018 | O29: =(O28+F29*$B$22)*(1+M29) -> 19389.869 | P29: =I29+L29+O29 -> 31407.923 | Q29: =H29+K29+N29 -> 2228.9842 | R29: =IF(Q29>0,Q29*$B$11,0) -> 624.11557 | S29: =26*$B$13 -> 27997.84 | T29: =P29-R29+S29 -> 58781.647
A30: 33 | B30: =_xlfn.NORM.INV(RAND(),$B$5,$B$6) -> 0.030119556 | C30: =C29*(1+B30) -> 72109.399 | D30: =IF(C30<84000,3%*(1-30%),3%*(1-33%)) -> 0.021 | E30: =$B$15 -> 521.43 | F30: =C30*($B$9+D30)+E30 -> 9246.6673 | G30: =_xlfn.NORM.INV(RAND(),$C$20,$D$20) -> 0.080808884 | H30: =(I29+F30*$B$20)*G30 -> 304.48729 | I30: =(I29+(F30*$B$20))*(1+G30) -> 4072.48 | J30: =_xlfn.NORM.INV(RAND(),$C$21,$D$21) -> 0.16054056 | K30: =(L29+F30*$B$21)*J30 -> 1844.0321 | L30: =(L29+F30*$B$21)*(1+J30) -> 13330.426 | M30: =_xlfn.NORM.INV(RAND(),$C$22,$D$22) -> 0.017246443 | N30: =(O29+F30*$B$22)*M30 -> 438.06316 | O30: =(O29+F30*$B$22)*(1+M30) -> 25838.266 | P30: =I30+L30+O30 -> 43241.172 | Q30: =H30+K30+N30 -> 2586.5826 | R30: =IF(Q30>0,Q30*$B$11,0) -> 724.24312 | S30: =26*$B$13 -> 27997.84 | T30: =P30-R30+S30 -> 70514.769
A31: 34 | B31: =_xlfn.NORM.INV(RAND(),$B$5,$B$6) -> 0.039398914 | C31: =C30*(1+B31) -> 74950.431 | D31: =IF(C31<84000,3%*(1-30%),3%*(1-33%)) -> 0.021 | E31: =$B$15 -> 521.43 | F31: =C31*($B$9+D31)+E31 -> 9590.4322 | G31: =_xlfn.NORM.INV(RAND(),$C$20,$D$20) -> 0.022212206 | H31: =(I30+F31*$B$20)*G31 -> 111.76123 | I31: =(I30+(F31*$B$20))*(1+G31) -> 5143.2845 | J31: =_xlfn.NORM.INV(RAND(),$C$21,$D$21) -> -0.11575324 | K31: =(L30+F31*$B$21)*J31 -> -1820.5709 | L31: =(L30+F31*$B$21)*(1+J31) -> 13907.464 | M31: =_xlfn.NORM.INV(RAND(),$C$22,$D$22) -> 0.35493223 | N31: =(O30+F31*$B$22)*M31 -> 11383.403 | O31: =(O30+F31*$B$22)*(1+M31) -> 43455.45 | P31: =I31+L31+O31 -> 62506.198 | Q31: =H31+K31+N31 -> 9674.5933 | R31: =IF(Q31>0,Q31*$B$11,0) -> 2708.8861 | S31: =26*$B$13 -> 27997.84 | T31: =P31-R31+S31 -> 87795.152
A32: 35 | B32: =_xlfn.NORM.INV(RAND(),$B$5,$B$6) -> 0.035129141 | C32: =C31*(1+B32) -> 77583.375 | D32: =IF(C32<84000,3%*(1-30%),3%*(1-33%)) -> 0.021 | E32: =$B$15 -> 521.43 | F32: =C32*($B$9+D32)+E32 -> 9909.0184 | G32: =_xlfn.NORM.INV(RAND(),$C$20,$D$20) -> 0.10321141 | H32: =(I31+F32*$B$20)*G32 -> 633.11802 | I32: =(I31+(F32*$B$20))*(1+G32) -> 6767.3043 | J32: =_xlfn.NORM.INV(RAND(),$C$21,$D$21) -> 0.063301326 | K32: =(L31+F32*$B$21)*J32 -> 1037.1744 | L32: =(L31+F32*$B$21)*(1+J32) -> 17421.893 | M32: =_xlfn.NORM.INV(RAND(),$C$22,$D$22) -> 0.21233462 | N32: =(O31+F32*$B$22)*M32 -> 10594.714 | O32: =(O31+F32*$B$22)*(1+M32) -> 60491.026 | P32: =I32+L32+O32 -> 84680.223 | Q32: =H32+K32+N32 -> 12265.007 | R32: =IF(Q32>0,Q32*$B$11,0) -> 3434.2019 | S32: =26*$B$13 -> 27997.84 | T32: =P32-R32+S32 -> 109243.86
A33: 36 | B33: =_xlfn.NORM.INV(RAND(),$B$5,$B$6) -> 0.027665954 | C33: =C32*(1+B33) -> 79729.793 | D33: =IF(C33<84000,3%*(1-30%),3%*(1-33%)) -> 0.021 | E33: =$B$15 -> 521.43 | F33: =C33*($B$9+D33)+E33 -> 10168.735 | G33: =_xlfn.NORM.INV(RAND(),$C$20,$D$20) -> 0.015140994 | H33: =(I32+F33*$B$20)*G33 -> 117.86019 | I33: =(I32+(F33*$B$20))*(1+G33) -> 7902.038 | J33: =_xlfn.NORM.INV(RAND(),$C$21,$D$21) -> 0.0618178 | K33: =(L32+F33*$B$21)*J33 -> 1234.1353 | L33: =(L32+F33*$B$21)*(1+J33) -> 21198.212 | M33: =_xlfn.NORM.INV(RAND(),$C$22,$D$22) -> -0.41795848 | N33: =(O32+F33*$B$22)*M33 -> -28045.308 | O33: =(O32+F33*$B$22)*(1+M33) -> 39055.396 | P33: =I33+L33+O33 -> 68155.646 | Q33: =H33+K33+N33 -> -26693.313 | R33: =IF(Q33>0,Q33*$B$11,0) -> 0 | S33: =26*$B$13 -> 27997.84 | T33: =P33-R33+S33 -> 96153.486
A34: 37 | B34: =_xlfn.NORM.INV(RAND(),$B$5,$B$6) -> 0.040716011 | C34: =C33*(1+B34) -> 82976.073 | D34: =IF(C34<84000,3%*(1-30%),3%*(1-33%)) -> 0.021 | E34: =$B$15 -> 521.43 | F34: =C34*($B$9+D34)+E34 -> 10561.535 | G34: =_xlfn.NORM.INV(RAND(),$C$20,$D$20) -> -0.055309184 | H34: =(I33+F34*$B$20)*G34 -> -495.47026 | I34: =(I33+(F34*$B$20))*(1+G34) -> 8462.7212 | J34: =_xlfn.NORM.INV(RAND(),$C$21,$D$21) -> -0.072838043 | K34: =(L33+F34*$B$21)*J34 -> -1736.3566 | L34: =(L33+F34*$B$21)*(1+J34) -> 22102.239 | M34: =_xlfn.NORM.INV(RAND(),$C$22,$D$22) -> -0.15785879 | N34: =(O33+F34*$B$22)*M34 -> -7248.9378 | O34: =(O33+F34*$B$22)*(1+M34) -> 38671.456 | P34: =I34+L34+O34 -> 69236.416 | Q34: =H34+K34+N34 -> -9480.7647 | R34: =IF(Q34>0,Q34*$B$11,0) -> 0 | S34: =26*$B$13 -> 27997.84 | T34: =P34-R34+S34 -> 97234.256
A35: 38 | B35: =_xlfn.NORM.INV(RAND(),$B$5,$B$6) -> 0.029252459 | C35: =C34*(1+B35) -> 85403.327 | D35: =IF(C35<84000,3%*(1-30%),3%*(1-33%)) -> 0.0201 | E35: =$B$15 -> 521.43 | F35: =C35*($B$9+D35)+E35 -> 10778.37 | G35: =_xlfn.NORM.INV(RAND(),$C$20,$D$20) -> 0.089060681 | H35: =(I34+F35*$B$20)*G35 -> 849.68861 | I35: =(I34+(F35*$B$20))*(1+G35) -> 10390.247 | J35: =_xlfn.NORM.INV(RAND(),$C$21,$D$21) -> 0.15577325 | K35: =(L34+F35*$B$21)*J35 -> 3862.6828 | L35: =(L34+F35*$B$21)*(1+J35) -> 28659.514 | M35: =_xlfn.NORM.INV(RAND(),$C$22,$D$22) -> 0.19929564 | N35: =(O34+F35*$B$22)*M35 -> 9103.3058 | O35: =(O34+F35*$B$22)*(1+M35) -> 54780.702 | P35: =I35+L35+O35 -> 93830.463 | Q35: =H35+K35+N35 -> 13815.677 | R35: =IF(Q35>0,Q35*$B$11,0) -> 3868.3896 | S35: =26*$B$13 -> 27997.84 | T35: =P35-R35+S35 -> 117959.91
A36: 39 | B36: =_xlfn.NORM.INV(RAND(),$B$5,$B$6) -> 0.034622039 | C36: =C35*(1+B36) -> 88360.164 | D36: =IF(C36<84000,3%*(1-30%),3%*(1-33%)) -> 0.0201 | E36: =$B$15 -> 521.43 | F36: =C36*($B$9+D36)+E36 -> 11133.486 | G36: =_xlfn.NORM.INV(RAND(),$C$20,$D$20) -> 0.083781491 | H36: =(I35+F36*$B$20)*G36 -> 963.78837 | I36: =(I35+(F36*$B$20))*(1+G36) -> 12467.384 | J36: =_xlfn.NORM.INV(RAND(),$C$21,$D$21) -> -0.03545421 | K36: =(L35+F36*$B$21)*J36 -> -1114.7827 | L36: =(L35+F36*$B$21)*(1+J36) -> 30328.103 | M36: =_xlfn.NORM.INV(RAND(),$C$22,$D$22) -> 0.32915117 | N36: =(O35+F36*$B$22)*M36 -> 20413.122 | O36: =(O35+F36*$B$22)*(1+M36) -> 82430.59 | P36: =I36+L36+O36 -> 125226.08 | Q36: =H36+K36+N36 -> 20262.128 | R36: =IF(Q36>0,Q36*$B$11,0) -> 5673.3958 | S36: =26*$B$13 -> 27997.84 | T36: =P36-R36+S36 -> 147550.52
A37: 40 | B37: =_xlfn.NORM.INV(RAND(),$B$5,$B$6) -> 0.028731509 | C37: =C36*(1+B37) -> 90898.885 | D37: =IF(C37<84000,3%*(1-30%),3%*(1-33%)) -> 0.0201 | E37: =$B$15 -> 521.43 | F37: =C37*($B$9+D37)+E37 -> 11438.386 | G37: =_xlfn.NORM.INV(RAND(),$C$20,$D$20) -> 0.088113399 | H37: =(I36+F37*$B$20)*G37 -> 1199.3311 | I37: =(I36+(F37*$B$20))*(1+G37) -> 14810.553 | J37: =_xlfn.NORM.INV(RAND(),$C$21,$D$21) -> 0.043301792 | K37: =(L36+F37*$B$21)*J37 -> 1437.0869 | L37: =(L36+F37*$B$21)*(1+J37) -> 34624.786 | M37: =_xlfn.NORM.INV(RAND(),$C$22,$D$22) -> -0.084279754 | N37: =(O36+F37*$B$22)*M37 -> -7573.8457 | O37: =(O36+F37*$B$22)*(1+M37) -> 82291.695 | P37: =I37+L37+O37 -> 131727.03 | Q37: =H37+K37+N37 -> -4937.4278 | R37: =IF(Q37>0,Q37*$B$11,0) -> 0 | S37: =26*$B$13 -> 27997.84 | T37: =P37-R37+S37 -> 159724.87
A38: 41 | B38: =_xlfn.NORM.INV(RAND(),$B$5,$B$6) -> 0.031976879 | C38: =C37*(1+B38) -> 93805.547 | D38: =IF(C38<84000,3%*(1-30%),3%*(1-33%)) -> 0.0201 | E38: =$B$15 -> 521.43 | F38: =C38*($B$9+D38)+E38 -> 11787.476 | G38: =_xlfn.NORM.INV(RAND(),$C$20,$D$20) -> -0.022778132 | H38: =(I37+F38*$B$20)*G38 -> -364.20641 | I38: =(I37+(F38*$B$20))*(1+G38) -> 15625.095 | J38: =_xlfn.NORM.INV(RAND(),$C$21,$D$21) -> -0.07020051 | K38: =(L37+F38*$B$21)*J38 -> -2637.5493 | L38: =(L37+F38*$B$21)*(1+J38) -> 34934.106 | M38: =_xlfn.NORM.INV(RAND(),$C$22,$D$22) -> 0.27741865 | N38: =(O37+F38*$B$22)*M38 -> 24954.794 | O38: =(O37+F38*$B$22)*(1+M38) -> 114908.35 | P38: =I38+L38+O38 -> 165467.55 | Q38: =H38+K38+N38 -> 21953.038 | R38: =IF(Q38>0,Q38*$B$11,0) -> 6146.8507 | S38: =26*$B$13 -> 27997.84 | T38: =P38-R38+S38 -> 187318.54
A39: 42 | B39: =_xlfn.NORM.INV(RAND(),$B$5,$B$6) -> 0.031771625 | C39: =C38*(1+B39) -> 96785.902 | D39: =IF(C39<84000,3%*(1-30%),3%*(1-33%)) -> 0.0201 | E39: =$B$15 -> 521.43 | F39: =C39*($B$9+D39)+E39 -> 12145.417 | G39: =_xlfn.NORM.INV(RAND(),$C$20,$D$20) -> 0.027993708 | H39: =(I38+F39*$B$20)*G39 -> 471.40386 | I39: =(I38+(F39*$B$20))*(1+G39) -> 17311.04 | J39: =_xlfn.NORM.INV(RAND(),$C$21,$D$21) -> 0.11946474 | K39: =(L38+F39*$B$21)*J39 -> 4536.1309 | L39: =(L38+F39*$B$21)*(1+J39) -> 42506.591 | M39: =_xlfn.NORM.INV(RAND(),$C$22,$D$22) -> 0.1606009 | N39: =(O38+F39*$B$22)*M39 -> 19722.252 | O39: =(O38+F39*$B$22)*(1+M39) -> 142525.12 | P39: =I39+L39+O39 -> 202342.75 | Q39: =H39+K39+N39 -> 24729.787 | R39: =IF(Q39>0,Q39*$B$11,0) -> 6924.3403 | S39: =26*$B$13 -> 27997.84 | T39: =P39-R39+S39 -> 223416.25
A40: 43 | B40: =_xlfn.NORM.INV(RAND(),$B$5,$B$6) -> 0.036962691 | C40: =C39*(1+B40) -> 100363.37 | D40: =IF(C40<84000,3%*(1-30%),3%*(1-33%)) -> 0.0201 | E40: =$B$15 -> 521.43 | F40: =C40*($B$9+D40)+E40 -> 12575.071 | G40: =_xlfn.NORM.INV(RAND(),$C$20,$D$20) -> 0.046776818 | H40: =(I39+F40*$B$20)*G40 -> 868.57755 | I40: =(I39+(F40*$B$20))*(1+G40) -> 19437.125 | J40: =_xlfn.NORM.INV(RAND(),$C$21,$D$21) -> 0.13220687 | K40: =(L39+F40*$B$21)*J40 -> 6035.2909 | L40: =(L39+F40*$B$21)*(1+J40) -> 51685.649 | M40: =_xlfn.NORM.INV(RAND(),$C$22,$D$22) -> -0.020956164 | N40: =(O39+F40*$B$22)*M40 -> -3158.0712 | O40: =(O39+F40*$B$22)*(1+M40) -> 147540.85 | P40: =I40+L40+O40 -> 218663.62 | Q40: =H40+K40+N40 -> 3745.7972 | R40: =IF(Q40>0,Q40*$B$11,0) -> 1048.8232 | S40: =26*$B$13 -> 27997.84 | T40: =P40-R40+S40 -> 245612.64
...

Sheet Neutral scenario 
A1: EMILY'S RETIREMENT MODEL
A3: Parameter | B3: 3910149
A4: current salary: | B4: 70000 | C4: (rand) | D4: =RAND() -> 0.54259986
A5: average growth rate/ yearly （ μ）： | B5: 0.035
A6: Standard variation（σ）： | B6: 0.007
A7: Estimated growth rate(norm) | B7: =_xlfn.NORM.INV(D4,B5,B6) -> 0.0357489
A8: Estimated salary | B8: =B4*(1+B7) -> 72502.423
A9: Contribution rate from Emily | B9: 0.06 | C9: 0.03 | D9: 0.06 | E9: 0.1
A10: superannuation rate from company | B10: 0.021 | C10: Deduct ESCT tax ($57,601 – $84,000) | D10: ESCT tax (> $84,000) | E10: Contribute based on pre-tax salary.
A11: KiwiSaver revenue tax(before retirement) | B11: 0.28
A12: KiwiSaver revenue tax(after retirement) | C12: NZ Super+bank intrest+fund revenue
A13: NZ Super tax | B13: 1076.84
A14: superannuation compensation from goverment | B14: =IF(B8*B9>C15,D15,B8*B9*50%) -> 521.43 | C14: Min personal contribute | D14: Max Member Tax Credit
C15: 1042.86 | D15: 521.43
A16: Annual Bank Savings | B16: =C17*(1+D17) -> 5581.242 | C16: Money saved per year | D16: Rate
C17: 5364 | D17: 0.0405
A18: Decision Variables | B18: Current allocation | C18: Annual Growth Rate | D18: Volatility （SD）
A19: Harbor safe | B19: 0.2 | C19: 0.0375 | D19: 0.05
A20: Horizon | B20: 0.3 | C20: 0.065 | D20: 0.105
A21: Skyhigh | B21: 0.5 | C21: 0.1025 | D21: 0.2075
A22: Total | B22: =SUM(B19:B21) -> 1
A23: Retirement age | B23: 63 | C23: 60 | D23: 63 | E23: 65 | F23: 0.03
B24: NORM.INV(D4,B5,B6) | C24: C19*(1+B20) | D24: IF(C10<84000,3%*(1-C13),3%*(1-D13)) | E24: IF(B8*B9>C13,D13,B8*B9*50%) | F24: C20*(B11+D20)+B14
A25: Year old（30-65 years old） | B25: Salary growth rate | C25: estimated salary | D25: superannuation rate from company | E25: superannuation compensation from gov | F25: Annual superannuation (pre-tax) | G25: Harbor safe growth rate | H25: Harborsafe revenue | I25: Harborsafe balance | J25: Horizon growth rate | K25: Horizon revenue | L25: Horizon balance | M25: Skyhigh growth rate | N25: Skyhigh revenue | O25: Skyhigh balance | P25: Total balance (pre tax) | Q25: Amount needs taxed | R25: Kiwisaver TAX | S25: NZ super | T25: Total Balance( after tax)
A26: 30 | B26: =_xlfn.NORM.INV(RAND(),$B$5,$B$6) -> 0.023086291 | C26: 70000 | D26: =IF(C26<84000,3%*(1-30%),3%*(1-33%)) -> 0.021 | E26: =$B$14 -> 521.43 | F26: =C26*($B$9+D26)+E26 -> 6191.43 | G26: =_xlfn.NORM.INV(RAND(),$C$19,$D$19) -> 0.0022208217 | H26: =(F26*$B$19)*G26 -> 2.7500124 | I26: =F26*B19*(1+G26) -> 1241.036 | J26: =_xlfn.NORM.INV(RAND(),$C$20,$D$20) -> 0.060037692 | K26: =F26*$B$20*J26 -> 111.51575 | L26: =F26*B20*(1+J26) -> 1968.9448 | M26: =_xlfn.NORM.INV(RAND(),$C$21,$D$21) -> 0.25860405 | N26: =F26*$B$21*M26 -> 800.56443 | O26: =F26*B21*(1+M26) -> 3896.2794 | P26: =I26+L26+O26 -> 7106.2602 | Q26: =H26+K26+N26 -> 914.8302 | R26: =IF(Q26>0,Q26*$B$11,0) -> 256.15246 | S26: =26*$B$13 -> 27997.84 | T26: =P26-R26+S26 -> 34847.948
A27: 31 | B27: =_xlfn.NORM.INV(RAND(),$B$5,$B$6) -> 0.018586821 | C27: =C26*(1+B27) -> 71301.077 | D27: =IF(C27<84000,3%*(1-30%),3%*(1-33%)) -> 0.021 | E27: =$B$14 -> 521.43 | F27: =C27*($B$9+D27)+E27 -> 6296.8173 | G27: =_xlfn.NORM.INV(RAND(),$C$19,$D$19) -> 0.12135885 | H27: =(I26+F27*$B$19)*G27 -> 303.44561 | I27: =(I26+(F27*$B$19))*(1+G27) -> 2803.8451 | J27: =_xlfn.NORM.INV(RAND(),$C$20,$D$20) -> -0.063887829 | K27: =(L26+F27*$B$20)*J27 -> -246.4786 | L27: =(L26+F27*$B$20)*(1+J27) -> 3611.5113 | M27: =_xlfn.NORM.INV(RAND(),$C$21,$D$21) -> 0.11487398 | N27: =(O26+F27*$B$21)*M27 -> 809.25135 | O27: =(O26+F27*$B$21)*(1+M27) -> 7853.9394 | P27: =I27+L27+O27 -> 14269.296 | Q27: =H27+K27+N27 -> 866.21836 | R27: =IF(Q27>0,Q27*$B$11,0) -> 242.54114 | S27: =26*$B$13 -> 27997.84 | T27: =P27-R27+S27 -> 42024.595
A28: 32 | B28: =_xlfn.NORM.INV(RAND(),$B$5,$B$6) -> 0.030249302 | C28: 70001 | D28: =IF(C28<84000,3%*(1-30%),3%*(1-33%)) -> 0.021 | E28: =$B$14 -> 521.43 | F28: =C28*($B$9+D28)+E28 -> 6191.511 | G28: =_xlfn.NORM.INV(RAND(),$C$19,$D$19) -> 0.021154084 | H28: =(I27+F28*$B$19)*G28 -> 85.507925 | I28: =(I27+(F28*$B$19))*(1+G28) -> 4127.6552 | J28: =_xlfn.NORM.INV(RAND(),$C$20,$D$20) -> 0.1274051 | K28: =(L27+F28*$B$20)*J28 -> 696.77397 | L28: =(L27+F28*$B$20)*(1+J28) -> 6165.7386 | M28: =_xlfn.NORM.INV(RAND(),$C$21,$D$21) -> 0.085485678 | N28: =(O27+F28*$B$21)*M28 -> 936.04209 | O28: =(O27+F28*$B$21)*(1+M28) -> 11885.737 | P28: =I28+L28+O28 -> 22179.131 | Q28: =H28+K28+N28 -> 1718.324 | R28: =IF(Q28>0,Q28*$B$11,0) -> 481.13071 | S28: =26*$B$13 -> 27997.84 | T28: =P28-R28+S28 -> 49695.84
A29: 33 | B29: =_xlfn.NORM.INV(RAND(),$B$5,$B$6) -> 0.026812615 | C29: =C28*(1+B29) -> 71877.91 | D29: =IF(C29<84000,3%*(1-30%),3%*(1-33%)) -> 0.021 | E29: =$B$14 -> 521.43 | F29: =C29*($B$9+D29)+E29 -> 6343.5407 | G29: =_xlfn.NORM.INV(RAND(),$C$19,$D$19) -> 0.13755063 | H29: =(I28+F29*$B$19)*G29 -> 742.27316 | I29: =(I28+(F29*$B$19))*(1+G29) -> 6138.6365 | J29: =_xlfn.NORM.INV(RAND(),$C$20,$D$20) -> -0.060198112 | K29: =(L28+F29*$B$20)*J29 -> -485.72658 | L29: =(L28+F29*$B$20)*(1+J29) -> 7583.0742 | M29: =_xlfn.NORM.INV(RAND(),$C$21,$D$21) -> 0.1904455 | N29: =(O28+F29*$B$21)*M29 -> 2867.6346 | O29: =(O28+F29*$B$21)*(1+M29) -> 17925.142 | P29: =I29+L29+O29 -> 31646.853 | Q29: =H29+K29+N29 -> 3124.1811 | R29: =IF(Q29>0,Q29*$B$11,0) -> 874.77072 | S29: =26*$B$13 -> 27997.84 | T29: =P29-R29+S29 -> 58769.922
A30: 34 | B30: =_xlfn.NORM.INV(RAND(),$B$5,$B$6) -> 0.048734406 | C30: =C29*(1+B30) -> 75380.837 | D30: =IF(C30<84000,3%*(1-30%),3%*(1-33%)) -> 0.021 | E30: =$B$14 -> 521.43 | F30: =C30*($B$9+D30)+E30 -> 6627.2778 | G30: =_xlfn.NORM.INV(RAND(),$C$19,$D$19) -> 0.0045141188 | H30: =(I29+F30*$B$19)*G30 -> 33.693799 | I30: =(I29+(F30*$B$19))*(1+G30) -> 7497.7859 | J30: =_xlfn.NORM.INV(RAND(),$C$20,$D$20) -> 0.065532212 | K30: =(L29+F30*$B$20)*J30 -> 627.22568 | L30: =(L29+F30*$B$20)*(1+J30) -> 10198.483 | M30: =_xlfn.NORM.INV(RAND(),$C$21,$D$21) -> -0.49635148 | N30: =(O29+F30*$B$21)*M30 -> -10541.9 | O30: =(O29+F30*$B$21)*(1+M30) -> 10696.88 | P30: =I30+L30+O30 -> 28393.15 | Q30: =H30+K30+N30 -> -9880.9809 | R30: =IF(Q30>0,Q30*$B$11,0) -> 0 | S30: =26*$B$13 -> 27997.84 | T30: =P30-R30+S30 -> 56390.99
A31: 35 | B31: =_xlfn.NORM.INV(RAND(),$B$5,$B$6) -> 0.035537931 | C31: =C30*(1+B31) -> 78059.716 | D31: =IF(C31<84000,3%*(1-30%),3%*(1-33%)) -> 0.021 | E31: =$B$14 -> 521.43 | F31: =C31*($B$9+D31)+E31 -> 6844.267 | G31: =_xlfn.NORM.INV(RAND(),$C$19,$D$19) -> 0.067191498 | H31: =(I30+F31*$B$19)*G31 -> 595.76277 | I31: =(I30+(F31*$B$19))*(1+G31) -> 9462.402 | J31: =_xlfn.NORM.INV(RAND(),$C$20,$D$20) -> 0.019651643 | K31: =(L30+F31*$B$20)*J31 -> 240.76728 | L31: =(L30+F31*$B$20)*(1+J31) -> 12492.531 | M31: =_xlfn.NORM.INV(RAND(),$C$21,$D$21) -> 0.14278926 | N31: =(O30+F31*$B$21)*M31 -> 2016.0436 | O31: =(O30+F31*$B$21)*(1+M31) -> 16135.058 | P31: =I31+L31+O31 -> 38089.99 | Q31: =H31+K31+N31 -> 2852.5736 | R31: =IF(Q31>0,Q31*$B$11,0) -> 798.72062 | S31: =26*$B$13 -> 27997.84 | T31: =P31-R31+S31 -> 65289.11
A32: 36 | B32: =_xlfn.NORM.INV(RAND(),$B$5,$B$6) -> 0.031972488 | C32: =C31*(1+B32) -> 80555.479 | D32: =IF(C32<84000,3%*(1-30%),3%*(1-33%)) -> 0.021 | E32: =$B$14 -> 521.43 | F32: =C32*($B$9+D32)+E32 -> 7046.4238 | G32: =_xlfn.NORM.INV(RAND(),$C$19,$D$19) -> 0.076980501 | H32: =(I31+F32*$B$19)*G32 -> 836.90789 | I32: =(I31+(F32*$B$19))*(1+G32) -> 11708.595 | J32: =_xlfn.NORM.INV(RAND(),$C$20,$D$20) -> 0.06780081 | K32: =(L31+F32*$B$20)*J32 -> 990.32967 | L32: =(L31+F32*$B$20)*(1+J32) -> 15596.787 | M32: =_xlfn.NORM.INV(RAND(),$C$21,$D$21) -> 0.037359101 | N32: =(O31+F32*$B$21)*M32 -> 734.41527 | O32: =(O31+F32*$B$21)*(1+M32) -> 20392.685 | P32: =I32+L32+O32 -> 47698.067 | Q32: =H32+K32+N32 -> 2561.6528 | R32: =IF(Q32>0,Q32*$B$11,0) -> 717.26279 | S32: =26*$B$13 -> 27997.84 | T32: =P32-R32+S32 -> 74978.644
A33: 37 | B33: =_xlfn.NORM.INV(RAND(),$B$5,$B$6) -> 0.048925036 | C33: =C32*(1+B33) -> 84496.659 | D33: =IF(C33<84000,3%*(1-30%),3%*(1-33%)) -> 0.0201 | E33: =$B$14 -> 521.43 | F33: =C33*($B$9+D33)+E33 -> 7289.6124 | G33: =_xlfn.NORM.INV(RAND(),$C$19,$D$19) -> 0.090164952 | H33: =(I32+F33*$B$19)*G33 -> 1187.1584 | I33: =(I32+(F33*$B$19))*(1+G33) -> 14353.676 | J33: =_xlfn.NORM.INV(RAND(),$C$20,$D$20) -> 0.060475179 | K33: =(L32+F33*$B$20)*J33 -> 1075.4707 | L33: =(L32+F33*$B$20)*(1+J33) -> 18859.142 | M33: =_xlfn.NORM.INV(RAND(),$C$21,$D$21) -> 0.011297334 | N33: =(O32+F33*$B$21)*M33 -> 271.55956 | O33: =(O32+F33*$B$21)*(1+M33) -> 24309.05 | P33: =I33+L33+O33 -> 57521.868 | Q33: =H33+K33+N33 -> 2534.1886 | R33: =IF(Q33>0,Q33*$B$11,0) -> 709.57282 | S33: =26*$B$13 -> 27997.84 | T33: =P33-R33+S33 -> 84810.135
A34: 38 | B34: =_xlfn.NORM.INV(RAND(),$B$5,$B$6) -> 0.039789106 | C34: =C33*(1+B34) -> 87858.706 | D34: =IF(C34<84000,3%*(1-30%),3%*(1-33%)) -> 0.0201 | E34: =$B$14 -> 521.43 | F34: =C34*($B$9+D34)+E34 -> 7558.9123 | G34: =_xlfn.NORM.INV(RAND(),$C$19,$D$19) -> 0.020045727 | H34: =(I33+F34*$B$19)*G34 -> 318.03464 | I34: =(I33+(F34*$B$19))*(1+G34) -> 16183.493 | J34: =_xlfn.NORM.INV(RAND(),$C$20,$D$20) -> 0.097907321 | K34: =(L33+F34*$B$20)*J34 -> 2068.4699 | L34: =(L33+F34*$B$20)*(1+J34) -> 23195.285 | M34: =_xlfn.NORM.INV(RAND(),$C$21,$D$21) -> -0.12107688 | N34: =(O33+F34*$B$21)*M34 -> -3400.8689 | O34: =(O33+F34*$B$21)*(1+M34) -> 24687.638 | P34: =I34+L34+O34 -> 64066.416 | Q34: =H34+K34+N34 -> -1014.3643 | R34: =IF(Q34>0,Q34*$B$11,0) -> 0 | S34: =26*$B$13 -> 27997.84 | T34: =P34-R34+S34 -> 92064.256
A35: 39 | B35: =_xlfn.NORM.INV(RAND(),$B$5,$B$6) -> 0.044303056 | C35: =C34*(1+B35) -> 91751.115 | D35: =IF(C35<84000,3%*(1-30%),3%*(1-33%)) -> 0.0201 | E35: =$B$14 -> 521.43 | F35: =C35*($B$9+D35)+E35 -> 7870.6943 | G35: =_xlfn.NORM.INV(RAND(),$C$19,$D$19) -> 0.029005087 | H35: =(I34+F35*$B$19)*G35 -> 515.06164 | I35: =(I34+(F35*$B$19))*(1+G35) -> 18272.693 | J35: =_xlfn.NORM.INV(RAND(),$C$20,$D$20) -> 0.0797277 | K35: =(L34+F35*$B$20)*J35 -> 2037.5605 | L35: =(L34+F35*$B$20)*(1+J35) -> 27594.054 | M35: =_xlfn.NORM.INV(RAND(),$C$21,$D$21) -> 0.13762021 | N35: =(O34+F35*$B$21)*M35 -> 3939.1011 | O35: =(O34+F35*$B$21)*(1+M35) -> 32562.086 | P35: =I35+L35+O35 -> 78428.833 | Q35: =H35+K35+N35 -> 6491.7232 | R35: =IF(Q35>0,Q35*$B$11,0) -> 1817.6825 | S35: =26*$B$13 -> 27997.84 | T35: =P35-R35+S35 -> 104608.99
A36: 40 | B36: =_xlfn.NORM.INV(RAND(),$B$5,$B$6) -> 0.03629439 | C36: =C35*(1+B36) -> 95081.166 | D36: =IF(C36<84000,3%*(1-30%),3%*(1-33%)) -> 0.0201 | E36: =$B$14 -> 521.43 | F36: =C36*($B$9+D36)+E36 -> 8137.4314 | G36: =_xlfn.NORM.INV(RAND(),$C$19,$D$19) -> 0.21291917 | H36: =(I35+F36*$B$19)*G36 -> 4237.1296 | I36: =(I35+(F36*$B$19))*(1+G36) -> 24137.309 | J36: =_xlfn.NORM.INV(RAND(),$C$20,$D$20) -> 0.22779501 | K36: =(L35+F36*$B$20)*J36 -> 6841.8878 | L36: =(L35+F36*$B$20)*(1+J36) -> 36877.171 | M36: =_xlfn.NORM.INV(RAND(),$C$21,$D$21) -> 0.45644241 | N36: =(O35+F36*$B$21)*M36 -> 16719.851 | O36: =(O35+F36*$B$21)*(1+M36) -> 53350.653 | P36: =I36+L36+O36 -> 114365.13 | Q36: =H36+K36+N36 -> 27798.869 | R36: =IF(Q36>0,Q36*$B$11,0) -> 7783.6833 | S36: =26*$B$13 -> 27997.84 | T36: =P36-R36+S36 -> 134579.29
A37: 41 | B37: =_xlfn.NORM.INV(RAND(),$B$5,$B$6) -> 0.04017256 | C37: =C36*(1+B37) -> 98900.819 | D37: =IF(C37<84000,3%*(1-30%),3%*(1-33%)) -> 0.0201 | E37: =$B$14 -> 521.43 | F37: =C37*($B$9+D37)+E37 -> 8443.3856 | G37: =_xlfn.NORM.INV(RAND(),$C$19,$D$19) -> 0.05613659 | H37: =(I36+F37*$B$19)*G37 -> 1449.7828 | I37: =(I36+(F37*$B$19))*(1+G37) -> 27275.769 | J37: =_xlfn.NORM.INV(RAND(),$C$20,$D$20) -> 0.057768784 | K37: =(L36+F37*$B$20)*J37 -> 2276.6786 | L37: =(L36+F37*$B$20)*(1+J37) -> 41686.866 | M37: =_xlfn.NORM.INV(RAND(),$C$21,$D$21) -> -0.13281333 | N37: =(O36+F37*$B$21)*M37 -> -7646.3748 | O37: =(O36+F37*$B$21)*(1+M37) -> 49925.971 | P37: =I37+L37+O37 -> 118888.61 | Q37: =H37+K37+N37 -> -3919.9134 | R37: =IF(Q37>0,Q37*$B$11,0) -> 0 | S37: =26*$B$13 -> 27997.84 | T37: =P37-R37+S37 -> 146886.45
A38: 42 | B38: =_xlfn.NORM.INV(RAND(),$B$5,$B$6) -> 0.034094801 | C38: =C37*(1+B38) -> 102272.82 | D38: =IF(C38<84000,3%*(1-30%),3%*(1-33%)) -> 0.0201 | E38: =$B$14 -> 521.43 | F38: =C38*($B$9+D38)+E38 -> 8713.4831 | G38: =_xlfn.NORM.INV(RAND(),$C$19,$D$19) -> 0.12094766 | H38: =(I37+F38*$B$19)*G38 -> 3509.7156 | I38: =(I37+(F38*$B$19))*(1+G38) -> 32528.181 | J38: =_xlfn.NORM.INV(RAND(),$C$20,$D$20) -> -0.027467188 | K38: =(L37+F38*$B$20)*J38 -> -1216.8214 | L38: =(L37+F38*$B$20)*(1+J38) -> 43084.089 | M38: =_xlfn.NORM.INV(RAND(),$C$21,$D$21) -> 0.3618874 | N38: =(O37+F38*$B$21)*M38 -> 19644.23 | O38: =(O37+F38*$B$21)*(1+M38) -> 73926.942 | P38: =I38+L38+O38 -> 149539.21 | Q38: =H38+K38+N38 -> 21937.124 | R38: =IF(Q38>0,Q38*$B$11,0) -> 6142.3947 | S38: =26*$B$13 -> 27997.84 | T38: =P38-R38+S38 -> 171394.66
A39: 43 | B39: =_xlfn.NORM.INV(RAND(),$B$5,$B$6) -> 0.03562993 | C39: =C38*(1+B39) -> 105916.8 | D39: =IF(C39<84000,3%*(1-30%),3%*(1-33%)) -> 0.0201 | E39: =$B$14 -> 521.43 | F39: =C39*($B$9+D39)+E39 -> 9005.3654 | G39: =_xlfn.NORM.INV(RAND(),$C$19,$D$19) -> 0.018426325 | H39: =(I38+F39*$B$19)*G39 -> 632.562 | I39: =(I38+(F39*$B$19))*(1+G39) -> 34961.816 | J39: =_xlfn.NORM.INV(RAND(),$C$20,$D$20) -> 0.094213248 | K39: =(L38+F39*$B$20)*J39 -> 4313.6194 | L39: =(L38+F39*$B$20)*(1+J39) -> 50099.318 | M39: =_xlfn.NORM.INV(RAND(),$C$21,$D$21) -> 0.22934566 | N39: =(O38+F39*$B$21)*M39 -> 17987.494 | O39: =(O38+F39*$B$21)*(1+M39) -> 96417.119 | P39: =I39+L39+O39 -> 181478.25 | Q39: =H39+K39+N39 -> 22933.676 | R39: =IF(Q39>0,Q39*$B$11,0) -> 6421.4292 | S39: =26*$B$13 -> 27997.84 | T39: =P39-R39+S39 -> 203054.66
A40: 44 | B40: =_xlfn.NORM.INV(RAND(),$B$5,$B$6) -> 0.04621668 | C40: =C39*(1+B40) -> 110811.92 | D40: =IF(C40<84000,3%*(1-30%),3%*(1-33%)) -> 0.0201 | E40: =$B$14 -> 521.43 | F40: =C40*($B$9+D40)+E40 -> 9397.4647 | G40: =_xlfn.NORM.INV(RAND(),$C$19,$D$19) -> 0.11958228 | H40: =(I39+F40*$B$19)*G40 -> 4405.5679 | I40: =(I39+(F40*$B$19))*(1+G40) -> 41246.877 | J40: =_xlfn.NORM.INV(RAND(),$C$20,$D$20) -> 0.048798526 | K40: =(L39+F40*$B$20)*J40 -> 2582.3476 | L40: =(L39+F40*$B$20)*(1+J40) -> 55500.905 | M40: =_xlfn.NORM.INV(RAND(),$C$21,$D$21) -> 0.22361685 | N40: =(O39+F40*$B$21)*M40 -> 22611.209 | O40: =(O39+F40*$B$21)*(1+M40) -> 123727.06 | P40: =I40+L40+O40 -> 220474.84 | Q40: =H40+K40+N40 -> 29599.124 | R40: =IF(Q40>0,Q40*$B$11,0) -> 8287.7548 | S40: =26*$B$13 -> 27997.84 | T40: =P40-R40+S40 -> 240184.93
... A59: 63 | B59: =_xlfn.NORM.INV(RAND(),$B$5,$B$6) -> 0.035177849 | C59: =C58*(1+B59) -> 193636.7 | D59: =IF(C59<84000,3%*(1-30%),3%*(1-33%)) -> 0.0201 | E59: =$B$14 -> 521.43 | F59: =C59*($B$9+D59)+E59 -> 16031.729 | G59: =_xlfn.NORM.INV(RAND(),$C$19,$D$19) -> 0.072547985 | H59: =(I58+F59*$B$19)*G59 -> 9156.5471 | I59: =(I58+(F59*$B$19))*(1+G59) -> 135370.21 | J59: =_xlfn.NORM.INV(RAND(),$C$20,$D$20) -> -0.099343302 | K59: =(L58+F59*$B$20)*J59 -> -20629.963 | L59: =(L58+F59*$B$20)*(1+J59) -> 187033.39 | M59: =_xlfn.NORM.INV(RAND(),$C$21,$D$21) -> 0.36874664 | N59: =(O58+F59*$B$21)*M59 -> 101761.66 | O59: =(O58+F59*$B$21)*(1+M59) -> 377728.01 | P59: =I59+L59+O59 -> 700131.61 | Q59: =H59+K59+N59 -> 90288.248 | R59: =IF(Q59>0,Q59*$B$11,0) -> 25280.709 | S59: =26*$B$13 -> 27997.84 | T59: =P59-R59+S59 -> 702848.74
...

Sheet Worst scenario
A1: EMILY'S RETIREMENT MODEL
A3: Parameter
A4: current salary: | B4: 70000 | C4: (rand) | D4: =RAND() -> 0.31454696
A5: average growth rate/ yearly （ μ）： | B5: 0.035
A6: Standard variation（σ）： | B6: 0.007
A7: Estimated growth rate(norm) | B7: =_xlfn.NORM.INV(D4,B5,B6) -> 0.031618982
A8: Estimated salary | B8: =B4*(1+B7) -> 72213.329
A9: Contribution rate from Emily | B9: 0.03 | C9: 0.03 | D9: 0.06 | E9: 0.1
A10: superannuation rate from company | B10: 0.021 | C10: Deduct ESCT tax ($57,601 – $84,000) | D10: ESCT tax (> $84,000) | E10: Contribute based on pre-tax salary.
A11: KiwiSaver revenue tax(before retirement) | B11: 0.28
A12: KiwiSaver revenue tax(after retirement) | C12: NZ Super+bank intrest+fund revenue
A13: NZ Super tax | B13: 1076.84
A14: superannuation compensation from goverment | B14: =IF(B8*B9>C15,D15,B8*B9*50%) -> 521.43 | C14: Min personal contribute | D14: Max Member Tax Credit
C15: 1042.86 | D15: 521.43
A16: Annual Bank Savings | B16: =C17*(1+D17) -> 5581.242 | C16: Money saved per year | D16: Rate
C17: 5364 | D17: 0.0405
A18: Decision Variables | B18: Current allocation | C18: Annual Growth Rate | D18: Volatility （SD）
A19: Harbor safe | B19: 0.4 | C19: 0.0375 | D19: 0.05
A20: Horizon | B20: 0.3 | C20: 0.065 | D20: 0.105
A21: Skyhigh | B21: 0.3 | C21: 0.1025 | D21: 0.2075
A22: Total | B22: =SUM(B19:B21) -> 1
A23: Retirement age | B23: 60 | C23: 60 | D23: 63 | E23: 65
F24: 0.03
B25: NORM.INV(D4,B5,B6) | C25: C19*(1+B20) | D25: IF(C10<84000,3%*(1-C13),3%*(1-D13)) | E25: IF(B8*B9>C13,D13,B8*B9*50%) | F25: C20*(B11+D20)+B14
A26: Year old（30-65 years old） | B26: Salary growth rate | C26: estimated salary | D26: superannuation rate from company | E26: superannuation compensation from gov | F26: Annual superannuation (pre-tax) | G26: Harbor safe growth rate | H26: Harborsafe revenue | I26: Harborsafe balance | J26: Horizon growth rate | K26: Horizon revenue | L26: Horizon balance | M26: Skyhigh growth rate | N26: Skyhigh revenue | O26: Skyhigh balance | P26: Total balance (pre tax) | Q26: Amount needs taxed | R26: Kiwisaver TAX | S26: NZ super | T26: Total Balance( after tax)
A27: 30 | B27: =_xlfn.NORM.INV(RAND(),$B$5,$B$6) -> 0.034041556 | C27: 70000 | D27: =IF(C27<84000,3%*(1-30%),3%*(1-33%)) -> 0.021 | E27: =$B$14 -> 521.43 | F27: =C27*($B$9+D27)+E27 -> 4091.43 | G27: =_xlfn.NORM.INV(RAND(),$C$19,$D$19) -> 0.057169888 | H27: =(F27*$B$19)*G27 -> 93.562638 | I27: =F27*B20*(1+G27) -> 1297.601 | J27: =_xlfn.NORM.INV(RAND(),$C$20,$D$20) -> 0.072363751 | K27: =F27*$B$20*J27 -> 88.821366 | L27: =F27*B21*(1+J27) -> 1316.2504 | M27: =_xlfn.NORM.INV(RAND(),$C$21,$D$21) -> 0.11653358 | N27: =F27*$B$21*M27 -> 143.03669 | O27: =F27*B22*(1+M27) -> 4568.219 | P27: =I27+L27+O27 -> 7182.0703 | Q27: =H27+K27+N27 -> 325.42069 | R27: =IF(Q27>0,Q27*$B$11,0) -> 91.117794 | S27: =26*$B$13 -> 27997.84 | T27: =P27-R27+S27 -> 35088.793
A28: 31 | B28: =_xlfn.NORM.INV(RAND(),$B$5,$B$6) -> 0.035711792 | C28: =C27*(1+B28) -> 72499.825 | D28: =IF(C28<84000,3%*(1-30%),3%*(1-33%)) -> 0.021 | E28: =$B$14 -> 521.43 | F28: =C28*($B$9+D28)+E28 -> 4218.9211 | G28: =_xlfn.NORM.INV(RAND(),$C$19,$D$19) -> 0.069402698 | H28: =(I27+F28*$B$19)*G28 -> 207.17881 | I28: =(I27+(F28*$B$19))*(1+G28) -> 3192.3482 | J28: =_xlfn.NORM.INV(RAND(),$C$20,$D$20) -> 0.23517553 | K28: =(L27+F28*$B$20)*J28 -> 607.20597 | L28: =(L27+F28*$B$20)*(1+J28) -> 3189.1327 | M28: =_xlfn.NORM.INV(RAND(),$C$21,$D$21) -> -0.33593082 | N28: =(O27+F28*$B$21)*M28 -> -1959.7853 | O28: =(O27+F28*$B$21)*(1+M28) -> 3874.11 | P28: =I28+L28+O28 -> 10255.591 | Q28: =H28+K28+N28 -> -1145.4005 | R28: =IF(Q28>0,Q28*$B$11,0) -> 0 | S28: =26*$B$13 -> 27997.84 | T28: =P28-R28+S28 -> 38253.431
A29: 32 | B29: =_xlfn.NORM.INV(RAND(),$B$5,$B$6) -> 0.033908332 | C29: 70001 | D29: =IF(C29<84000,3%*(1-30%),3%*(1-33%)) -> 0.021 | E29: =$B$14 -> 521.43 | F29: =C29*($B$9+D29)+E29 -> 4091.481 | G29: =_xlfn.NORM.INV(RAND(),$C$19,$D$19) -> 0.011964981 | H29: =(I28+F29*$B$19)*G29 -> 57.778184 | I29: =(I28+(F29*$B$19))*(1+G29) -> 4886.7188 | J29: =_xlfn.NORM.INV(RAND(),$C$20,$D$20) -> 0.14927292 | K29: =(L28+F29*$B$20)*J29 -> 659.27534 | L29: =(L28+F29*$B$20)*(1+J29) -> 5075.8523 | M29: =_xlfn.NORM.INV(RAND(),$C$21,$D$21) -> 0.082653448 | N29: =(O28+F29*$B$21)*M29 -> 421.66106 | O29: =(O28+F29*$B$21)*(1+M29) -> 5523.2154 | P29: =I29+L29+O29 -> 15485.787 | Q29: =H29+K29+N29 -> 1138.7146 | R29: =IF(Q29>0,Q29*$B$11,0) -> 318.84008 | S29: =26*$B$13 -> 27997.84 | T29: =P29-R29+S29 -> 43164.786
A30: 33 | B30: =_xlfn.NORM.INV(RAND(),$B$5,$B$6) -> 0.040114549 | C30: =C29*(1+B30) -> 72809.059 | D30: =IF(C30<84000,3%*(1-30%),3%*(1-33%)) -> 0.021 | E30: =$B$14 -> 521.43 | F30: =C30*($B$9+D30)+E30 -> 4234.692 | G30: =_xlfn.NORM.INV(RAND(),$C$19,$D$19) -> 0.08422204 | H30: =(I29+F30*$B$19)*G30 -> 554.23118 | I30: =(I29+(F30*$B$19))*(1+G30) -> 7134.8268 | J30: =_xlfn.NORM.INV(RAND(),$C$20,$D$20) -> 0.065613895 | K30: =(L29+F30*$B$20)*J30 -> 416.40283 | L30: =(L29+F30*$B$20)*(1+J30) -> 6762.6627 | M30: =_xlfn.NORM.INV(RAND(),$C$21,$D$21) -> -0.26222376 | N30: =(O29+F30*$B$21)*M30 -> -1781.4494 | O30: =(O29+F30*$B$21)*(1+M30) -> 5012.1736 | P30: =I30+L30+O30 -> 18909.663 | Q30: =H30+K30+N30 -> -810.81535 | R30: =IF(Q30>0,Q30*$B$11,0) -> 0 | S30: =26*$B$13 -> 27997.84 | T30: =P30-R30+S30 -> 46907.503
A31: 34 | B31: =_xlfn.NORM.INV(RAND(),$B$5,$B$6) -> 0.036403391 | C31: =C30*(1+B31) -> 75459.555 | D31: =IF(C31<84000,3%*(1-30%),3%*(1-33%)) -> 0.021 | E31: =$B$14 -> 521.43 | F31: =C31*($B$9+D31)+E31 -> 4369.8673 | G31: =_xlfn.NORM.INV(RAND(),$C$19,$D$19) -> 0.12062208 | H31: =(I30+F31*$B$19)*G31 -> 1071.4586 | I31: =(I30+(F31*$B$19))*(1+G31) -> 9954.2323 | J31: =_xlfn.NORM.INV(RAND(),$C$20,$D$20) -> -0.057904579 | K31: =(L30+F31*$B$20)*J31 -> -467.49973 | L31: =(L30+F31*$B$20)*(1+J31) -> 7606.1232 | M31: =_xlfn.NORM.INV(RAND(),$C$21,$D$21) -> 0.05859683 | N31: =(O30+F31*$B$21)*M31 -> 370.51559 | O31: =(O30+F31*$B$21)*(1+M31) -> 6693.6494 | P31: =I31+L31+O31 -> 24254.005 | Q31: =H31+K31+N31 -> 974.47446 | R31: =IF(Q31>0,Q31*$B$11,0) -> 272.85285 | S31: =26*$B$13 -> 27997.84 | T31: =P31-R31+S31 -> 51978.992
A32: 35 | B32: =_xlfn.NORM.INV(RAND(),$B$5,$B$6) -> 0.038943348 | C32: =C31*(1+B32) -> 78398.203 | D32: =IF(C32<84000,3%*(1-30%),3%*(1-33%)) -> 0.021 | E32: =$B$14 -> 521.43 | F32: =C32*($B$9+D32)+E32 -> 4519.7383 | G32: =_xlfn.NORM.INV(RAND(),$C$19,$D$19) -> 0.074504612 | H32: =(I31+F32*$B$19)*G32 -> 876.33275 | I32: =(I31+(F32*$B$19))*(1+G32) -> 12638.46 | J32: =_xlfn.NORM.INV(RAND(),$C$20,$D$20) -> 0.032872267 | K32: =(L31+F32*$B$20)*J32 -> 294.60273 | L32: =(L31+F32*$B$20)*(1+J32) -> 9256.6474 | M32: =_xlfn.NORM.INV(RAND(),$C$21,$D$21) -> 0.36859843 | N32: =(O31+F32*$B$21)*M32 -> 2967.0592 | O32: =(O31+F32*$B$21)*(1+M32) -> 11016.63 | P32: =I32+L32+O32 -> 32911.738 | Q32: =H32+K32+N32 -> 4137.9946 | R32: =IF(Q32>0,Q32*$B$11,0) -> 1158.6385 | S32: =26*$B$13 -> 27997.84 | T32: =P32-R32+S32 -> 59750.939
A33: 36 | B33: =_xlfn.NORM.INV(RAND(),$B$5,$B$6) -> 0.035050687 | C33: =C32*(1+B33) -> 81146.114 | D33: =IF(C33<84000,3%*(1-30%),3%*(1-33%)) -> 0.021 | E33: =$B$14 -> 521.43 | F33: =C33*($B$9+D33)+E33 -> 4659.8818 | G33: =_xlfn.NORM.INV(RAND(),$C$19,$D$19) -> 0.024453563 | H33: =(I32+F33*$B$19)*G33 -> 354.63567 | I33: =(I32+(F33*$B$19))*(1+G33) -> 14857.049 | J33: =_xlfn.NORM.INV(RAND(),$C$20,$D$20) -> 0.14942095 | K33: =(L32+F33*$B$20)*J33 -> 1592.0223 | L33: =(L32+F33*$B$20)*(1+J33) -> 12246.634 | M33: =_xlfn.NORM.INV(RAND(),$C$21,$D$21) -> 0.14119403 | N33: =(O32+F33*$B$21)*M33 -> 1752.8666 | O33: =(O32+F33*$B$21)*(1+M33) -> 14167.461 | P33: =I33+L33+O33 -> 41271.144 | Q33: =H33+K33+N33 -> 3699.5246 | R33: =IF(Q33>0,Q33*$B$11,0) -> 1035.8669 | S33: =26*$B$13 -> 27997.84 | T33: =P33-R33+S33 -> 68233.117
A34: 37 | B34: =_xlfn.NORM.INV(RAND(),$B$5,$B$6) -> 0.024234904 | C34: =C33*(1+B34) -> 83112.682 | D34: =IF(C34<84000,3%*(1-30%),3%*(1-33%)) -> 0.021 | E34: =$B$14 -> 521.43 | F34: =C34*($B$9+D34)+E34 -> 4760.1768 | G34: =_xlfn.NORM.INV(RAND(),$C$19,$D$19) -> 0.0060139597 | H34: =(I33+F34*$B$19)*G34 -> 100.8007 | I34: =(I33+(F34*$B$19))*(1+G34) -> 16861.92 | J34: =_xlfn.NORM.INV(RAND(),$C$20,$D$20) -> 0.16697686 | K34: =(L33+F34*$B$20)*J34 -> 2283.3564 | L34: =(L33+F34*$B$20)*(1+J34) -> 15958.044 | M34: =_xlfn.NORM.INV(RAND(),$C$21,$D$21) -> -0.17385086 | N34: =(O33+F34*$B$21)*M34 -> -2711.2936 | O34: =(O33+F34*$B$21)*(1+M34) -> 12884.221 | P34: =I34+L34+O34 -> 45704.185 | Q34: =H34+K34+N34 -> -327.13651 | R34: =IF(Q34>0,Q34*$B$11,0) -> 0 | S34: =26*$B$13 -> 27997.84 | T34: =P34-R34+S34 -> 73702.025
A35: 38 | B35: =_xlfn.NORM.INV(RAND(),$B$5,$B$6) -> 0.034954299 | C35: =C34*(1+B35) -> 86017.828 | D35: =IF(C35<84000,3%*(1-30%),3%*(1-33%)) -> 0.0201 | E35: =$B$14 -> 521.43 | F35: =C35*($B$9+D35)+E35 -> 4830.9232 | G35: =_xlfn.NORM.INV(RAND(),$C$19,$D$19) -> -0.0054303651 | H35: =(I34+F35*$B$19)*G35 -> -102.05985 | I35: =(I34+(F35*$B$19))*(1+G35) -> 18692.23 | J35: =_xlfn.NORM.INV(RAND(),$C$20,$D$20) -> 0.082526049 | K35: =(L34+F35*$B$20)*J35 -> 1436.5574 | L35: =(L34+F35*$B$20)*(1+J35) -> 18843.878 | M35: =_xlfn.NORM.INV(RAND(),$C$21,$D$21) -> -0.08600079 | N35: =(O34+F35*$B$21)*M35 -> -1232.6921 | O35: =(O34+F35*$B$21)*(1+M35) -> 13100.805 | P35: =I35+L35+O35 -> 50636.913 | Q35: =H35+K35+N35 -> 101.80543 | R35: =IF(Q35>0,Q35*$B$11,0) -> 28.505521 | S35: =26*$B$13 -> 27997.84 | T35: =P35-R35+S35 -> 78606.248
A36: 39 | B36: =_xlfn.NORM.INV(RAND(),$B$5,$B$6) -> 0.034613721 | C36: =C35*(1+B36) -> 88995.225 | D36: =IF(C36<84000,3%*(1-30%),3%*(1-33%)) -> 0.0201 | E36: =$B$14 -> 521.43 | F36: =C36*($B$9+D36)+E36 -> 4980.0908 | G36: =_xlfn.NORM.INV(RAND(),$C$19,$D$19) -> -0.0067473029 | H36: =(I35+F36*$B$19)*G36 -> -139.56301 | I36: =(I35+(F36*$B$19))*(1+G36) -> 20544.703 | J36: =_xlfn.NORM.INV(RAND(),$C$20,$D$20) -> 0.201125 | K36: =(L35+F36*$B$20)*J36 -> 4090.4612 | L36: =(L35+F36*$B$20)*(1+J36) -> 24428.366 | M36: =_xlfn.NORM.INV(RAND(),$C$21,$D$21) -> 0.059341353 | N36: =(O35+F36*$B$21)*M36 -> 866.07713 | O36: =(O35+F36*$B$21)*(1+M36) -> 15460.91 | P36: =I36+L36+O36 -> 60433.979 | Q36: =H36+K36+N36 -> 4816.9754 | R36: =IF(Q36>0,Q36*$B$11,0) -> 1348.7531 | S36: =26*$B$13 -> 27997.84 | T36: =P36-R36+S36 -> 87083.066
A37: 40 | B37: =_xlfn.NORM.INV(RAND(),$B$5,$B$6) -> 0.025771866 | C37: =C36*(1+B37) -> 91288.798 | D37: =IF(C37<84000,3%*(1-30%),3%*(1-33%)) -> 0.0201 | E37: =$B$14 -> 521.43 | F37: =C37*($B$9+D37)+E37 -> 5094.9988 | G37: =_xlfn.NORM.INV(RAND(),$C$19,$D$19) -> 0.049125781 | H37: =(I36+F37*$B$19)*G37 -> 1109.3929 | I37: =(I36+(F37*$B$19))*(1+G37) -> 23692.095 | J37: =_xlfn.NORM.INV(RAND(),$C$20,$D$20) -> 0.14163334 | K37: =(L36+F37*$B$20)*J37 -> 3676.3576 | L37: =(L36+F37*$B$20)*(1+J37) -> 29633.224 | M37: =_xlfn.NORM.INV(RAND(),$C$21,$D$21) -> 0.28192389 | N37: =(O36+F37*$B$21)*M37 -> 4789.7203 | O37: =(O36+F37*$B$21)*(1+M37) -> 21779.13 | P37: =I37+L37+O37 -> 75104.449 | Q37: =H37+K37+N37 -> 9575.4708 | R37: =IF(Q37>0,Q37*$B$11,0) -> 2681.1318 | S37: =26*$B$13 -> 27997.84 | T37: =P37-R37+S37 -> 100421.16
A38: 41 | B38: =_xlfn.NORM.INV(RAND(),$B$5,$B$6) -> 0.034557116 | C38: =C37*(1+B38) -> 94443.475 | D38: =IF(C38<84000,3%*(1-30%),3%*(1-33%)) -> 0.0201 | E38: =$B$14 -> 521.43 | F38: =C38*($B$9+D38)+E38 -> 5253.0481 | G38: =_xlfn.NORM.INV(RAND(),$C$19,$D$19) -> 0.071340544 | H38: =(I37+F38*$B$19)*G38 -> 1840.1091 | I38: =(I37+(F38*$B$19))*(1+G38) -> 27633.424 | J38: =_xlfn.NORM.INV(RAND(),$C$20,$D$20) -> 0.0014234904 | K38: =(L37+F38*$B$20)*J38 -> 44.425907 | L38: =(L37+F38*$B$20)*(1+J38) -> 31253.564 | M38: =_xlfn.NORM.INV(RAND(),$C$21,$D$21) -> -0.10716494 | N38: =(O37+F38*$B$21)*M38 -> -2502.842 | O38: =(O37+F38*$B$21)*(1+M38) -> 20852.202 | P38: =I38+L38+O38 -> 79739.19 | Q38: =H38+K38+N38 -> -618.30698 | R38: =IF(Q38>0,Q38*$B$11,0) -> 0 | S38: =26*$B$13 -> 27997.84 | T38: =P38-R38+S38 -> 107737.03
A39: 42 | B39: =_xlfn.NORM.INV(RAND(),$B$5,$B$6) -> 0.034968881 | C39: =C38*(1+B39) -> 97746.058 | D39: =IF(C39<84000,3%*(1-30%),3%*(1-33%)) -> 0.0201 | E39: =$B$14 -> 521.43 | F39: =C39*($B$9+D39)+E39 -> 5418.5075 | G39: =_xlfn.NORM.INV(RAND(),$C$19,$D$19) -> -0.013852044 | H39: =(I38+F39*$B$19)*G39 -> -412.80236 | I39: =(I38+(F39*$B$19))*(1+G39) -> 29388.024 | J39: =_xlfn.NORM.INV(RAND(),$C$20,$D$20) -> -0.062582037 | K39: =(L38+F39*$B$20)*J39 -> -2057.6421 | L39: =(L38+F39*$B$20)*(1+J39) -> 30821.474 | M39: =_xlfn.NORM.INV(RAND(),$C$21,$D$21) -> -0.1197113 | N39: =(O38+F39*$B$21)*M39 -> -2690.8412 | O39: =(O38+F39*$B$21)*(1+M39) -> 19786.913 | P39: =I39+L39+O39 -> 79996.412 | Q39: =H39+K39+N39 -> -5161.2857 | R39: =IF(Q39>0,Q39*$B$11,0) -> 0 | S39: =26*$B$13 -> 27997.84 | T39: =P39-R39+S39 -> 107994.25
A40: 43 | B40: =_xlfn.NORM.INV(RAND(),$B$5,$B$6) -> 0.025146063 | C40: =C39*(1+B40) -> 100203.99 | D40: =IF(C40<84000,3%*(1-30%),3%*(1-33%)) -> 0.0201 | E40: =$B$14 -> 521.43 | F40: =C40*($B$9+D40)+E40 -> 5541.6497 | G40: =_xlfn.NORM.INV(RAND(),$C$19,$D$19) -> 0.057105778 | H40: =(I39+F40*$B$19)*G40 -> 1804.8101 | I40: =(I39+(F40*$B$19))*(1+G40) -> 33409.494 | J40: =_xlfn.NORM.INV(RAND(),$C$20,$D$20) -> 0.12816238 | K40: =(L39+F40*$B$20)*J40 -> 4163.2227 | L40: =(L39+F40*$B$20)*(1+J40) -> 36647.192 | M40: =_xlfn.NORM.INV(RAND(),$C$21,$D$21) -> 0.23375269 | N40: =(O39+F40*$B$21)*M40 -> 5013.8569 | O40: =(O39+F40*$B$21)*(1+M40) -> 26463.265 | P40: =I40+L40+O40 -> 96519.951 | Q40: =H40+K40+N40 -> 10981.89 | R40: =IF(Q40>0,Q40*$B$11,0) -> 3074.9291 | S40: =26*$B$13 -> 27997.84 | T40: =P40-R40+S40 -> 121442.86
A41: 44 | B41: =_xlfn.NORM.INV(RAND(),$B$5,$B$6) -> 0.038672742 | C41: =C40*(1+B41) -> 104079.15 | D41: =IF(C41<84000,3%*(1-30%),3%*(1-33%)) -> 0.0201 | E41: =$B$14 -> 521.43 | F41: =C41*($B$9+D41)+E41 -> 5735.7954 | G41: =_xlfn.NORM.INV(RAND(),$C$19,$D$19) -> 0.068717203 | H41: =(I40+F41*$B$19)*G41 -> 2453.4661 | I41: =(I40+(F41*$B$19))*(1+G41) -> 38157.279 | J41: =_xlfn.NORM.INV(RAND(),$C$20,$D$20) -> 0.006744756 | K41: =(L40+F41*$B$20)*J41 -> 258.78233 | L41: =(L40+F41*$B$20)*(1+J41) -> 38626.713 | M41: =_xlfn.NORM.INV(RAND(),$C$21,$D$21) -> 0.35428853 | N41: =(O40+F41*$B$21)*M41 -> 9985.2692 | O41: =(O40+F41*$B$21)*(1+M41) -> 38169.273 | P41: =I41+L41+O41 -> 114953.26 | Q41: =H41+K41+N41 -> 12697.518 | R41: =IF(Q41>0,Q41*$B$11,0) -> 3555.3049 | S41: =26*$B$13 -> 27997.84 | T41: =P41-R41+S41 -> 139395.8
...

Sheet Inflation rate & expenditure
D2: Min | F2: 0.001
D3: average | F3: 0.025643564
D4: Max | F4: 0.073
D5: SD | F5: 0.016450887
A7: Date | B7: CPI (Annual % change) | D7: AGE | E7: Inflation rate | F7: Average annual expenditure | G7: Total expenditure | J7: trial | K7: Total Expenditure | R7: Best senario | S7: AGE | T7: Inflation rate | U7: Average annual expenditure | V7: Total expenditure | W7: Cumalative expenditure | Y7: worst senario | Z7: AGE | AA7: Inflation rate | AB7: Average annaul expenditure | AC7: Total expenture | AD7: Cumalative expenditure
A8: 3/31/2000 | B8: 1.5 | D8: 65 | E8: 0.024008407 | F8: 39279.836 | G8: 40222.883 | J8: {=_xlfn.SEQUENCE(5000)} -> 1 | K8: =V34 -> 1043808.6 | M8: max | N8: =MAX(K8:K5007) -> 1054404.6 | S8: 65 | T8: =_xlfn.NORM.INV(RAND(),'Inflation rate & expenditure1'!E29,'Inflation rate & expenditure1'!E30) -> 0.0091686012 | U8: 39279.836 | V8: =U8*(1+T8) -> 39639.978 | W8: =V8 -> 39639.978 | Z8: 60 | AA8: =_xlfn.NORM.INV(RAND(),'Inflation rate & expenditure1'!$E$29,'Inflation rate & expenditure1'!$E$30) -> 0.026038213 | AB8: 39279.836 | AC8: =AB8*(1+AA8) -> 40302.613 | AD8: =AC8 -> 40302.613
A9: 6/30/2000 | B9: 2 | D9: 66 | E9: 0.04544144 | F9: 39279.836 | G9: 41064.769 | J9: 2 | K9: 1045974.1 | M9: min | N9: =MIN(K8:K5007) -> 1035686.7 | S9: 66 | T9: =_xlfn.NORM.INV(RAND(),'Inflation rate & expenditure1'!E29,'Inflation rate & expenditure1'!E30) -> 0.013419979 | U9: 39279.836 | V9: =U9*(1+T9) -> 39806.971 | W9: =V9+W8 -> 79446.949 | Z9: 61 | AA9: =_xlfn.NORM.INV(RAND(),'Inflation rate & expenditure1'!$E$29,'Inflation rate & expenditure1'!$E$30) -> 0.0022884717 | AB9: 39279.836 | AC9: =AB9*(1+AA9) -> 39369.727 | AD9: =AC9+AD8 -> 79672.34
A10: 9/30/2000 | B10: 3 | D10: 67 | E10: 0.021357737 | F10: 39279.836 | G10: 40118.765 | J10: 3 | K10: 1044323.6 | M10: mean | N10: =AVERAGE(K8:K5007) -> 1044988.2 | S10: 67 | T10: =_xlfn.NORM.INV(RAND(),'Inflation rate & expenditure1'!E29,'Inflation rate & expenditure1'!E30) -> 0.01766742 | U10: 39279.836 | V10: =U10*(1+T10) -> 39973.81 | W10: =V10+W9 -> 119420.76 | Z10: 62 | AA10: =_xlfn.NORM.INV(RAND(),'Inflation rate & expenditure1'!$E$29,'Inflation rate & expenditure1'!$E$30) -> 0.03353774 | AB10: 39279.836 | AC10: =AB10*(1+AA10) -> 40597.193 | AD10: =AC10+AD9 -> 120269.53
A11: 12/31/2000 | B11: 4 | D11: 68 | E11: 0.013409904 | F11: 39279.836 | G11: 39806.575 | J11: 4 | K11: 1048496.4 | M11: sd | N11: =_xlfn.STDEV.S(K8:K5007) -> 2671.3689 | S11: 68 | T11: =_xlfn.NORM.INV(RAND(),'Inflation rate & expenditure1'!E29,'Inflation rate & expenditure1'!E30) -> 0.054401346 | U11: 39279.836 | V11: =U11*(1+T11) -> 41416.712 | W11: =V11+W10 -> 160837.47 | Z11: 63 | AA11: =_xlfn.NORM.INV(RAND(),'Inflation rate & expenditure1'!$E$29,'Inflation rate & expenditure1'!$E$30) -> 0.049521619 | AB11: 39279.836 | AC11: =AB11*(1+AA11) -> 41225.037 | AD11: =AC11+AD10 -> 161494.57
A12: 3/31/2001 | B12: 3.1 | D12: 69 | E12: 0.0064509825 | F12: 39279.836 | G12: 39533.23 | J12: 5 | K12: 1042033.5 | M12: count | N12: =COUNT(K8:K5007) -> 5000 | S12: 69 | T12: =_xlfn.NORM.INV(RAND(),'Inflation rate & expenditure1'!E29,'Inflation rate & expenditure1'!E30) -> 0.032534327 | U12: 39279.836 | V12: =U12*(1+T12) -> 40557.779 | W12: =V12+W11 -> 201395.25 | Z12: 64 | AA12: =_xlfn.NORM.INV(RAND(),'Inflation rate & expenditure1'!$E$29,'Inflation rate & expenditure1'!$E$30) -> 0.012188187 | AB12: 39279.836 | AC12: =AB12*(1+AA12) -> 39758.586 | AD12: =AC12+AD11 -> 201253.16
A13: 6/30/2001 | B13: 3.2 | D13: 70 | E13: 0.0058239922 | F13: 39279.836 | G13: 39508.602 | J13: 6 | K13: 1050614.2 | S13: 70 | T13: =_xlfn.NORM.INV(RAND(),'Inflation rate & expenditure1'!E29,'Inflation rate & expenditure1'!E30) -> 0.0478443 | U13: 39279.836 | V13: =U13*(1+T13) -> 41159.153 | W13: =V13+W12 -> 242554.4 | Z13: 65 | AA13: =_xlfn.NORM.INV(RAND(),'Inflation rate & expenditure1'!$E$29,'Inflation rate & expenditure1'!$E$30) -> 0.025942822 | AB13: 39279.836 | AC13: =AB13*(1+AA13) -> 40298.866 | AD13: =AC13+AD12 -> 241552.02
A14: 9/30/2001 | B14: 2.4 | D14: 71 | E14: -0.018863775 | F14: 39279.836 | G14: 38538.87 | J14: 7 | K14: 1048413.4 | M14: Fixed expenditure | S14: 71 | T14: =_xlfn.NORM.INV(RAND(),'Inflation rate & expenditure1'!E29,'Inflation rate & expenditure1'!E30) -> 0.033779915 | U14: 39279.836 | V14: =U14*(1+T14) -> 40606.706 | W14: =V14+W13 -> 283161.11 | Z14: 66 | AA14: =_xlfn.NORM.INV(RAND(),'Inflation rate & expenditure1'!$E$29,'Inflation rate & expenditure1'!$E$30) -> 0.0021879312 | AB14: 39279.836 | AC14: =AB14*(1+AA14) -> 39365.778 | AD14: =AC14+AD13 -> 280917.8
A15: 12/31/2001 | B15: 1.8 | D15: 72 | E15: 0.015890055 | F15: 39279.836 | G15: 39903.995 | J15: 8 | K15: 1041547.6 | M15: Worst scenario | N15: 1185666.7 | S15: 72 | T15: =_xlfn.NORM.INV(RAND(),'Inflation rate & expenditure1'!E29,'Inflation rate & expenditure1'!E30) -> 0.024112897 | U15: 39279.836 | V15: =U15*(1+T15) -> 40226.987 | W15: =V15+W14 -> 323388.1 | Z15: 67 | AA15: =_xlfn.NORM.INV(RAND(),'Inflation rate & expenditure1'!$E$29,'Inflation rate & expenditure1'!$E$30) -> 0.041515489 | AB15: 39279.836 | AC15: =AB15*(1+AA15) -> 40910.558 | AD15: =AC15+AD14 -> 321828.36
A16: 3/31/2002 | B16: 2.6 | D16: 73 | E16: 0.044829112 | F16: 39279.836 | G16: 41040.717 | J16: 9 | K16: 1041364 | M16: Best scenario | N16: 1164278.3 | S16: 73 | T16: =_xlfn.NORM.INV(RAND(),'Inflation rate & expenditure1'!E29,'Inflation rate & expenditure1'!E30) -> 0.034749055 | U16: 39279.836 | V16: =U16*(1+T16) -> 40644.774 | W16: =V16+W15 -> 364032.87 | Z16: 68 | AA16: =_xlfn.NORM.INV(RAND(),'Inflation rate & expenditure1'!$E$29,'Inflation rate & expenditure1'!$E$30) -> 0.025652986 | AB16: 39279.836 | AC16: =AB16*(1+AA16) -> 40287.481 | AD16: =AC16+AD15 -> 362115.84
A17: 6/30/2002 | B17: 2.8 | D17: 74 | E17: 0.025374325 | F17: 39279.836 | G17: 40276.536 | J17: 10 | K17: 1039321.6 | M17: neutral scenario | N17: 1175187.8 | S17: 74 | T17: =_xlfn.NORM.INV(RAND(),'Inflation rate & expenditure1'!E29,'Inflation rate & expenditure1'!E30) -> 0.050592503 | U17: 39279.836 | V17: =U17*(1+T17) -> 41267.102 | W17: =V17+W16 -> 405299.97 | Z17: 69 | AA17: =_xlfn.NORM.INV(RAND(),'Inflation rate & expenditure1'!$E$29,'Inflation rate & expenditure1'!$E$30) -> 0.014879102 | AB17: 39279.836 | AC17: =AB17*(1+AA17) -> 39864.285 | AD17: =AC17+AD16 -> 401980.13
A18: 9/30/2002 | B18: 2.6 | D18: 75 | E18: 0.024976512 | F18: 39279.836 | G18: 40260.91 | J18: 11 | K18: 1048771.9 | M18: sd | N18: 2957.5255 | S18: 75 | T18: =_xlfn.NORM.INV(RAND(),'Inflation rate & expenditure1'!E29,'Inflation rate & expenditure1'!E30) -> 0.014030693 | U18: 39279.836 | V18: =U18*(1+T18) -> 39830.96 | W18: =V18+W17 -> 445130.93 | Z18: 70 | AA18: =_xlfn.NORM.INV(RAND(),'Inflation rate & expenditure1'!$E$29,'Inflation rate & expenditure1'!$E$30) -> 0.039752556 | AB18: 39279.836 | AC18: =AB18*(1+AA18) -> 40841.31 | AD18: =AC18+AD17 -> 442821.44
A19: 12/31/2002 | B19: 2.7 | D19: 76 | E19: 0.019162966 | F19: 39279.836 | G19: 40032.555 | J19: 12 | K19: 1045034 | M19: count | N19: 5000 | S19: 76 | T19: =_xlfn.NORM.INV(RAND(),'Inflation rate & expenditure1'!E29,'Inflation rate & expenditure1'!E30) -> 0.029567577 | U19: 39279.836 | V19: =U19*(1+T19) -> 40441.246 | W19: =V19+W18 -> 485572.18 | Z19: 71 | AA19: =_xlfn.NORM.INV(RAND(),'Inflation rate & expenditure1'!$E$29,'Inflation rate & expenditure1'!$E$30) -> 0.072584581 | AB19: 39279.836 | AC19: =AB19*(1+AA19) -> 42130.947 | AD19: =AC19+AD18 -> 484952.38
A20: 3/31/2003 | B20: 2.5 | D20: 77 | E20: 0.017357163 | F20: 39279.836 | G20: 39961.623 | J20: 13 | K20: 1046039.6 | S20: 77 | T20: =_xlfn.NORM.INV(RAND(),'Inflation rate & expenditure1'!E29,'Inflation rate & expenditure1'!E30) -> 0.015844581 | U20: 39279.836 | V20: =U20*(1+T20) -> 39902.209 | W20: =V20+W19 -> 525474.39 | Z20: 72 | AA20: =_xlfn.NORM.INV(RAND(),'Inflation rate & expenditure1'!$E$29,'Inflation rate & expenditure1'!$E$30) -> 0.037997109 | AB20: 39279.836 | AC20: =AB20*(1+AA20) -> 40772.357 | AD20: =AC20+AD19 -> 525724.74
A21: 6/30/2003 | B21: 1.5 | D21: 78 | E21: 0.023034767 | F21: 39279.836 | G21: 40184.638 | J21: 14 | K21: 1041847.7 | M21: 95% CI | N21: =N17-_xlfn.CONFIDENCE.T(0.05,N18,N12) -> 1175105.8 | S21: 78 | T21: =_xlfn.NORM.INV(RAND(),'Inflation rate & expenditure1'!E29,'Inflation rate & expenditure1'!E30) -> -0.0043107093 | U21: 39279.836 | V21: =U21*(1+T21) -> 39110.512 | W21: =V21+W20 -> 564584.9 | Z21: 73 | AA21: =_xlfn.NORM.INV(RAND(),'Inflation rate & expenditure1'!$E$29,'Inflation rate & expenditure1'!$E$30) -> 0.015057965 | AB21: 39279.836 | AC21: =AB21*(1+AA21) -> 39871.311 | AD21: =AC21+AD20 -> 565596.05
A22: 9/30/2003 | B22: 1.5 | D22: 79 | E22: 0.0017156173 | F22: 39279.836 | G22: 39347.226 | J22: 15 | K22: 1041759.4 | N22: =N17+_xlfn.CONFIDENCE.T(0.05,N18,N19) -> 1175269.8 | S22: 79 | T22: =_xlfn.NORM.INV(RAND(),'Inflation rate & expenditure1'!E29,'Inflation rate & expenditure1'!E30) -> 0.028305617 | U22: 39279.836 | V22: =U22*(1+T22) -> 40391.676 | W22: =V22+W21 -> 604976.57 | Z22: 74 | AA22: =_xlfn.NORM.INV(RAND(),'Inflation rate & expenditure1'!$E$29,'Inflation rate & expenditure1'!$E$30) -> -0.0072830945 | AB22: 39279.836 | AC22: =AB22*(1+AA22) -> 38993.758 | AD22: =AC22+AD21 -> 604589.81
A23: 12/31/2003 | B23: 1.6 | D23: 80 | E23: 0.002667952 | F23: 39279.836 | G23: 39384.633 | J23: 16 | K23: 1047367.7 | S23: 80 | T23: =_xlfn.NORM.INV(RAND(),'Inflation rate & expenditure1'!E29,'Inflation rate & expenditure1'!E30) -> 0.016626593 | U23: 39279.836 | V23: =U23*(1+T23) -> 39932.926 | W23: =V23+W22 -> 644909.5 | Z23: 75 | AA23: =_xlfn.NORM.INV(RAND(),'Inflation rate & expenditure1'!$E$29,'Inflation rate & expenditure1'!$E$30) -> 0.0054999067 | AB23: 39279.836 | AC23: =AB23*(1+AA23) -> 39495.872 | AD23: =AC23+AD22 -> 644085.68
A24: 3/31/2004 | B24: 1.5 | D24: 81 | E24: 0.032870432 | F24: 39279.836 | G24: 40570.982 | J24: 17 | K24: 1043977.7 | S24: 81 | T24: =_xlfn.NORM.INV(RAND(),'Inflation rate & expenditure1'!E29,'Inflation rate & expenditure1'!E30) -> 0.034401267 | U24: 39279.836 | V24: =U24*(1+T24) -> 40631.113 | W24: =V24+W23 -> 685540.61 | Z24: 76 | AA24: =_xlfn.NORM.INV(RAND(),'Inflation rate & expenditure1'!$E$29,'Inflation rate & expenditure1'!$E$30) -> 0.044097014 | AB24: 39279.836 | AC24: =AB24*(1+AA24) -> 41011.96 | AD24: =AC24+AD23 -> 685097.64
A25: 6/30/2004 | B25: 2.4 | D25: 82 | E25: 0.013467928 | F25: 39279.836 | G25: 39808.854 | J25: 18 | K25: 1043583.3 | M25: add: 60/63 retirement age expenditure | S25: 82 | T25: =_xlfn.NORM.INV(RAND(),'Inflation rate & expenditure1'!E29,'Inflation rate & expenditure1'!E30) -> 0.01166179 | U25: 39279.836 | V25: =U25*(1+T25) -> 39737.91 | W25: =V25+W24 -> 725278.52 | Z25: 77 | AA25: =_xlfn.NORM.INV(RAND(),'Inflation rate & expenditure1'!$E$29,'Inflation rate & expenditure1'!$E$30) -> 0.015379174 | AB25: 39279.836 | AC25: =AB25*(1+AA25) -> 39883.928 | AD25: =AC25+AD24 -> 724981.57
A26: 9/30/2004 | B26: 2.5 | D26: 83 | E26: 0.042635392 | F26: 39279.836 | G26: 40954.548 | J26: 19 | K26: 1045935.5 | S26: 83 | T26: =_xlfn.NORM.INV(RAND(),'Inflation rate & expenditure1'!E29,'Inflation rate & expenditure1'!E30) -> 0.032212287 | U26: 39279.836 | V26: =U26*(1+T26) -> 40545.13 | W26: =V26+W25 -> 765823.65 | Z26: 78 | AA26: =_xlfn.NORM.INV(RAND(),'Inflation rate & expenditure1'!$E$29,'Inflation rate & expenditure1'!$E$30) -> 0.014874265 | AB26: 39279.836 | AC26: =AB26*(1+AA26) -> 39864.095 | AD26: =AC26+AD25 -> 764845.66
A27: 12/31/2004 | B27: 2.7 | D27: 84 | E27: 0.013777679 | F27: 39279.836 | G27: 39821.021 | J27: 20 | K27: 1042733.3 | S27: 84 | T27: =_xlfn.NORM.INV(RAND(),'Inflation rate & expenditure1'!E29,'Inflation rate & expenditure1'!E30) -> -0.014631154 | U27: 39279.836 | V27: =U27*(1+T27) -> 38705.127 | W27: =V27+W26 -> 804528.78 | Z27: 79 | AA27: =_xlfn.NORM.INV(RAND(),'Inflation rate & expenditure1'!$E$29,'Inflation rate & expenditure1'!$E$30) -> 0.024392723 | AB27: 39279.836 | AC27: =AB27*(1+AA27) -> 40237.979 | AD27: =AC27+AD26 -> 805083.64
A28: 3/31/2005 | B28: 2.8 | E28: Emergency Fund(Total) | F28: 39279.836 | J28: 21 | K28: 1048038.3 | T28: Emergency Fund(Total) | U28: 39279.836 | Z28: 80 | AA28: =_xlfn.NORM.INV(RAND(),'Inflation rate & expenditure1'!$E$29,'Inflation rate & expenditure1'!$E$30) -> 0.035402836 | AB28: 39279.836
A29: 6/30/2005 | B29: 2.8 | E29: Children | F29: 130172 | J29: 22 | K29: 1045011 | T29: Children | U29: 130172 | Z29: 81 | AA29: =_xlfn.NORM.INV(RAND(),'Inflation rate & expenditure1'!$E$29,'Inflation rate & expenditure1'!$E$30) -> 0.033256051 | AB29: 39279.836
A30: 9/30/2005 | B30: 3.4 | E30: Traveling expenditure per year | F30: 10000 | J30: 23 | K30: 1042243.6 | T30: Traveling expenditure per year | U30: 10000 | Z30: 82 | AA30: =_xlfn.NORM.INV(RAND(),'Inflation rate & expenditure1'!$E$29,'Inflation rate & expenditure1'!$E$30) -> 0.035704476 | AB30: 39279.836
A31: 12/31/2005 | B31: 3.2 | E31: Retirement period | F31: 20 | J31: 24 | K31: 1043477.4 | T31: Retirement period | U31: 20 | Z31: 83 | AA31: =_xlfn.NORM.INV(RAND(),'Inflation rate & expenditure1'!$E$29,'Inflation rate & expenditure1'!$E$30) -> 0.010855109 | AB31: 39279.836
A32: 3/31/2006 | B32: 3.3 | J32: 25 | K32: 1050000.1 | Z32: 84 | AA32: =_xlfn.NORM.INV(RAND(),'Inflation rate & expenditure1'!$E$29,'Inflation rate & expenditure1'!$E$30) -> 0.013588318 | AB32: 39279.836
A33: 6/30/2006 | B33: 4 | F33: 785596.73 | G33: 800341.93 | J33: 26 | K33: 1043390.3 | U33: =SUM(U8:U27) -> 785596.73 | V33: =SUM(V8:V27) -> 804528.78 | AA33: Emergency Fund(Total) | AB33: 39279.836
A34: 9/30/2006 | B34: 3.5 | F34: TOTAL expenditure | G34: 1169793.8 | J34: 27 | K34: 1044314.4 | U34: Total expenditure | V34: =V33+U28+(U30*U31) -> 1043808.6 | AA34: Children | AB34: 130172
A35: 12/31/2006 | B35: 2.6 | J35: 28 | K35: 1043633 | AA35: Traveling expenditure per year | AB35: 10000
A36: 3/31/2007 | B36: 2.5 | J36: 29 | K36: 1045758.5 | AA36: Retirement period | AB36: 20
A37: 6/30/2007 | B37: 2 | J37: 30 | K37: 1043029.3
A38: 9/30/2007 | B38: 1.8 | J38: 31 | K38: 1045011.9 | AB38: =SUM(AB13:AB32) -> 785596.73 | AC38: =SUM(AC13:AC32) -> 603830.48
A39: 12/31/2007 | B39: 3.2 | J39: 32 | K39: 1051136.3 | AB39: Total expenditure | AC39: =AC38+AB33+AB34+(AB35*AB36) -> 973282.32
A40: 3/31/2008 | B40: 3.4 | J40: 33 | K40: 1042026.1
A41: 6/30/2008 | B41: 4 | J41: 34 | K41: 1047963.5
A42: 9/30/2008 | B42: 5.1 | J42: 35 | K42: 1043749.3
...

Sheet Inflation rate & expenditure1
A1: Date | B1: CPI (Annual % change) | D1: annual inflation | J1: Best senario | K1: AGE | L1: Inflation rate | M1: Average annual expenditure | N1: Total expenditure | O1: NZ Super(no inflation) | P1: NZ Super(inflation) | S1: worst scenario | T1: AGE | U1: Inflation rate | V1: Average annaul expenditure | W1: Total expenditure | X1: Cumulative expenditure | Z1: neutral scenario | AA1: AGE | AB1: Inflation rate | AC1: Average annaul expenditure | AD1: Total expenture | AE1: Cumulative expenditure
A2: 3/31/2000 | B2: 1.5 | D2: 2000 | E2: =AVERAGE(B2:B5)/100 -> 0.02625 | K2: {=_xlfn.SEQUENCE(55,1,30)} -> 30 | L2: =IF(RAND()<($E$37/$E$35),$E$32+SQRT(RAND()*$E$35*$E$37),$E$31-SQRT((1-RAND())*$E$36*$E$35)) -> 0.032330136 | M2: 39279.836 | N2: =M2*(1+L2) -> 40549.759 | O2: ='Best scenario'!$S$27 -> 27997.84 | P2: =O2*(1+L2) -> 28903.014 | T2: {=_xlfn.SEQUENCE(55,1,30)} -> 30 | U2: =IF(RAND()<($E$37/$E$35),$E$32+SQRT(RAND()*$E$35*$E$37),$E$31-SQRT((1-RAND())*$E$36*$E$35)) -> 0.037339937 | V2: 39279.836 | W2: =V2*(1+U2) -> 40746.543 | X2: =W2 -> 40746.543 | AA2: {=_xlfn.SEQUENCE(55,1,30)} -> 30 | AB2: =IF(RAND()<($E$37/$E$35),$E$32+SQRT(RAND()*$E$35*$E$37),$E$31-SQRT((1-RAND())*$E$36*$E$35)) -> 0.032765164 | AC2: 39279.836 | AD2: =AC2*(1+AB2) -> 40566.847 | AE2: =AD2 -> 40566.847
A3: 6/30/2000 | B3: 2 | D3: 2001 | E3: =AVERAGE(B6:B9)/100 -> 0.02625 | K3: 31 | L3: =IF(RAND()<($E$37/$E$35),$E$32+SQRT(RAND()*$E$35*$E$37),$E$31-SQRT((1-RAND())*$E$36*$E$35)) -> 0.03091307 | M3: 39279.836 | N3: =N2*(1+L3) -> 41803.276 | O3: ='Best scenario'!$S$27 -> 27997.84 | P3: =P2*(1+L3) -> 29796.495 | T3: 31 | U3: =IF(RAND()<($E$37/$E$35),$E$32+SQRT(RAND()*$E$35*$E$37),$E$31-SQRT((1-RAND())*$E$36*$E$35)) -> 0.025421482 | V3: 39279.836 | W3: =W2*(1+U3) -> 41782.381 | X3: =W3+X2 -> 82528.924 | AA3: 31 | AB3: =IF(RAND()<($E$37/$E$35),$E$32+SQRT(RAND()*$E$35*$E$37),$E$31-SQRT((1-RAND())*$E$36*$E$35)) -> 0.023494486 | AC3: 39279.836 | AD3: =AD2*(1+AB3) -> 41519.944 | AE3: =AE2+AD3 -> 82086.791
